Workbook

Sheet CE Schemes
A2: Date | B2: Manager | C2: OIC | D2: Reported -Major Leaks | E2: Reported -Minor Leaks | F2: Reported -Service Leaks | G2: Repaired -Major Leaks | H2: Repaired -Minor Leaks | I2: Repaired -Service Leaks | J2: Balance -Major Leaks | K2: Balance -Minor Leaks | L2: Balance -Service Leaks
A3: 46093 | B3: CE | C3: AMPITIYA | D3: {=XLOOKUP($A3, Ampitiya!$A7:$A65, Ampitiya!B7:B65, "No Match")} -> 4 | E3: {=XLOOKUP($A3, Ampitiya!$A7:$A65, Ampitiya!C7:C65, "No Match")} -> 2 | F3: {=XLOOKUP($A3, Ampitiya!$A7:$A65, Ampitiya!D7:D65, "No Match")} -> 1 | G3: {=XLOOKUP($A3, Ampitiya!$A7:$A65, Ampitiya!E7:E65, "No Match")} -> 1 | H3: {=XLOOKUP($A3, Ampitiya!$A7:$A65, Ampitiya!F7:F65, "No Match")} -> 2 | I3: {=XLOOKUP($A3, Ampitiya!$A7:$A65, Ampitiya!G7:G65, "No Match")} -> 1 | J3: {=XLOOKUP($A3, Ampitiya!$A7:$A65, Ampitiya!H7:H65, "No Match")} -> 3 | K3: {=XLOOKUP($A3, Ampitiya!$A7:$A65, Ampitiya!I7:I65, "No Match")} -> 0 | L3: {=XLOOKUP($A3, Ampitiya!$A7:$A65, Ampitiya!J7:J65, "No Match")} -> 0
A4: =$A$3 -> 46093 | B4: CE | C4: Digana 1 | D4: {=XLOOKUP($A4, 'Digana 1'!$A7:$A65, 'Digana 1'!B7:B65, "No Match")} -> 0 | E4: {=XLOOKUP($A4, 'Digana 1'!$A6:$A65, 'Digana 1'!C6:C65, "No Match")} -> 0 | F4: {=XLOOKUP($A4, 'Digana 1'!$A6:$A65, 'Digana 1'!D6:D65, "No Match")} -> 0 | G4: {=XLOOKUP($A4, 'Digana 1'!$A6:$A65, 'Digana 1'!E6:E65, "No Match")} -> 0 | H4: {=XLOOKUP($A4, 'Digana 1'!$A6:$A65, 'Digana 1'!F6:F65, "No Match")} -> 0 | I4: {=XLOOKUP($A4, 'Digana 1'!$A6:$A65, 'Digana 1'!G6:G65, "No Match")} -> 0 | J4: {=XLOOKUP($A4, 'Digana 1'!$A6:$A65, 'Digana 1'!H6:H65, "No Match")} -> 0 | K4: {=XLOOKUP($A4, 'Digana 1'!$A6:$A65, 'Digana 1'!I6:I65, "No Match")} -> 0 | L4: {=XLOOKUP($A4, 'Digana 1'!$A6:$A65, 'Digana 1'!J6:J65, "No Match")} -> 0
A5: =$A$3 -> 46093 | B5: CE | C5: Digana 2 | D5: {=XLOOKUP($A5, 'Digana 2'!$A7:$A65, 'Digana 2'!B7:B65, "No Match")} -> 0 | E5: {=XLOOKUP($A5, 'Digana 2'!$A7:$A65, 'Digana 2'!C7:C65, "No Match")} -> 1 | F5: {=XLOOKUP($A5, 'Digana 2'!$A7:$A65, 'Digana 2'!D7:D65, "No Match")} -> 0 | G5: {=XLOOKUP($A5, 'Digana 2'!$A7:$A65, 'Digana 2'!E7:E65, "No Match")} -> 0 | H5: {=XLOOKUP($A5, 'Digana 2'!$A7:$A65, 'Digana 2'!F7:F65, "No Match")} -> 1 | I5: {=XLOOKUP($A5, 'Digana 2'!$A7:$A65, 'Digana 2'!G7:G65, "No Match")} -> 0 | J5: {=XLOOKUP($A5, 'Digana 2'!$A7:$A65, 'Digana 2'!H7:H65, "No Match")} -> 0 | K5: {=XLOOKUP($A5, 'Digana 2'!$A7:$A65, 'Digana 2'!I7:I65, "No Match")} -> 0 | L5: {=XLOOKUP($A5, 'Digana 2'!$A7:$A65, 'Digana 2'!J7:J65, "No Match")} -> 0
A6: =$A$3 -> 46093 | B6: CE | C6: Balagolla | D6: {=XLOOKUP($A6, Balagolla!$A7:$A65, Balagolla!B7:B65, "No Match")} -> 0 | E6: {=XLOOKUP($A6, Balagolla!$A7:$A65, Balagolla!C7:C65, "No Match")} -> 0 | F6: {=XLOOKUP($A6, Balagolla!$A7:$A65, Balagolla!D7:D65, "No Match")} -> 2 | G6: {=XLOOKUP($A6, Balagolla!$A7:$A65, Balagolla!E7:E65, "No Match")} -> 0 | H6: {=XLOOKUP($A6, Balagolla!$A7:$A65, Balagolla!F7:F65, "No Match")} -> 0 | I6: {=XLOOKUP($A6, Balagolla!$A7:$A65, Balagolla!G7:G65, "No Match")} -> 2 | J6: {=XLOOKUP($A6, Balagolla!$A7:$A65, Balagolla!H7:H65, "No Match")} -> 0 | K6: {=XLOOKUP($A6, Balagolla!$A7:$A65, Balagolla!I7:I65, "No Match")} -> 0 | L6: {=XLOOKUP($A6, Balagolla!$A7:$A65, Balagolla!J7:J65, "No Match")} -> 0
A7: =$A$3 -> 46093 | B7: CE | C7: Manikhinna | D7: {=XLOOKUP($A7, Manikhinna!$A7:$A65, Manikhinna!B7:B65, "No Match")} -> 0 | E7: {=XLOOKUP($A7, Manikhinna!$A7:$A65, Manikhinna!C7:C65, "No Match")} -> 1 | F7: {=XLOOKUP($A7, Manikhinna!$A7:$A65, Manikhinna!D7:D65, "No Match")} -> 0 | G7: {=XLOOKUP($A7, Manikhinna!$A7:$A65, Manikhinna!E7:E65, "No Match")} -> 0 | H7: {=XLOOKUP($A7, Manikhinna!$A7:$A65, Manikhinna!F7:F65, "No Match")} -> 0 | I7: {=XLOOKUP($A7, Manikhinna!$A7:$A65, Manikhinna!G7:G65, "No Match")} -> 1 | J7: {=XLOOKUP($A7, Manikhinna!$A7:$A65, Manikhinna!H7:H65, "No Match")} -> 0 | K7: {=XLOOKUP($A7, Manikhinna!$A7:$A65, Manikhinna!I7:I65, "No Match")} -> 0 | L7: {=XLOOKUP($A7, Manikhinna!$A7:$A65, Manikhinna!J7:J65, "No Match")} -> 0
A8: =$A$3 -> 46093 | B8: CE | C8: Buluwamuduna | D8: {=XLOOKUP($A8, Buluwamuduna!$A7:$A65, Buluwamuduna!B7:B65, "No Match")} -> 1 | E8: {=XLOOKUP($A8, Buluwamuduna!$A7:$A65, Buluwamuduna!C7:C65, "No Match")} -> 1 | F8: {=XLOOKUP($A8, Buluwamuduna!$A7:$A65, Buluwamuduna!D7:D65, "No Match")} -> 2 | G8: {=XLOOKUP($A8, Buluwamuduna!$A7:$A65, Buluwamuduna!E7:E65, "No Match")} -> 0 | H8: {=XLOOKUP($A8, Buluwamuduna!$A7:$A65, Buluwamuduna!F7:F65, "No Match")} -> 0 | I8: {=XLOOKUP($A8, Buluwamuduna!$A7:$A65, Buluwamuduna!G7:G65, "No Match")} -> 2 | J8: {=XLOOKUP($A8, Buluwamuduna!$A7:$A65, Buluwamuduna!H7:H65, "No Match")} -> 1 | K8: {=XLOOKUP($A8, Buluwamuduna!$A7:$A65, Buluwamuduna!I7:I65, "No Match")} -> 1 | L8: {=XLOOKUP($A8, Buluwamuduna!$A7:$A65, Buluwamuduna!J7:J65, "No Match")} -> 0
A9: =$A$3 -> 46093 | B9: CE | C9: MEDADUMBARA | D9: {=XLOOKUP($A9, Medadumbara!$A9:$A65, Medadumbara!B9:B65, "No Match")} -> 0 | E9: {=XLOOKUP($A9, Medadumbara!$A9:$A65, Medadumbara!C9:C65, "No Match")} -> 2 | F9: {=XLOOKUP($A9, Medadumbara!$A9:$A65, Medadumbara!D9:D65, "No Match")} -> 3 | G9: {=XLOOKUP($A9, Medadumbara!$A9:$A65, Medadumbara!E9:E65, "No Match")} -> 0 | H9: {=XLOOKUP($A9, Medadumbara!$A9:$A65, Medadumbara!F9:F65, "No Match")} -> 0 | I9: {=XLOOKUP($A9, Medadumbara!$A9:$A65, Medadumbara!G9:G65, "No Match")} -> 0 | J9: {=XLOOKUP($A9, Medadumbara!$A9:$A65, Medadumbara!H9:H65, "No Match")} -> 0 | K9: {=XLOOKUP($A9, Medadumbara!$A9:$A65, Medadumbara!I9:I65, "No Match")} -> 0 | L9: {=XLOOKUP($A9, Medadumbara!$A9:$A65, Medadumbara!J9:J65, "No Match")} -> 0
A10: =$A$3 -> 46093 | B10: CE | C10: HARAGAMA | D10: {=XLOOKUP($A10, Haragama!$A7:$A65, Haragama!B7:B65, "No Match")} -> 0 | E10: {=XLOOKUP($A10, Haragama!$A7:$A65, Haragama!C7:C65, "No Match")} -> 1 | F10: {=XLOOKUP($A10, Haragama!$A7:$A65, Haragama!D7:D65, "No Match")} -> 1 | G10: {=XLOOKUP($A10, Haragama!$A7:$A65, Haragama!E7:E65, "No Match")} -> 0 | H10: {=XLOOKUP($A10, Haragama!$A7:$A65, Haragama!F7:F65, "No Match")} -> 1 | I10: {=XLOOKUP($A10, Haragama!$A7:$A65, Haragama!G7:G65, "No Match")} -> 1 | J10: {=XLOOKUP($A10, Haragama!$A7:$A65, Haragama!H7:H65, "No Match")} -> 0 | K10: {=XLOOKUP($A10, Haragama!$A7:$A65, Haragama!I7:I65, "No Match")} -> 1 | L10: {=XLOOKUP($A10, Haragama!$A7:$A65, Haragama!J7:J65, "No Match")} -> 1
A11: =$A$3 -> 46093 | B11: CE | C11: MARASSANA | D11: {=XLOOKUP($A11, Marassana!$A7:$A65, Marassana!B7:B65, "No Match")} -> 2 | E11: {=XLOOKUP($A11, Marassana!$A7:$A65, Marassana!C7:C65, "No Match")} -> 1 | F11: {=XLOOKUP($A11, Marassana!$A7:$A65, Marassana!D7:D65, "No Match")} -> 3 | G11: {=XLOOKUP($A11, Marassana!$A7:$A65, Marassana!E7:E65, "No Match")} -> 1 | H11: {=XLOOKUP($A11, Marassana!$A7:$A65, Marassana!F7:F65, "No Match")} -> 1 | I11: {=XLOOKUP($A11, Marassana!$A7:$A65, Marassana!G7:G65, "No Match")} -> 1 | J11: {=XLOOKUP($A11, Marassana!$A7:$A65, Marassana!H7:H65, "No Match")} -> 0 | K11: {=XLOOKUP($A11, Marassana!$A7:$A65, Marassana!I7:I65, "No Match")} -> 0 | L11: {=XLOOKUP($A11, Marassana!$A7:$A65, Marassana!J7:J65, "No Match")} -> 0
A12: =$A$3 -> 46093 | B12: CE | C12: RIKILLAGASKADA | D12: 1 | E12: 3 | F12: 0 | G12: {=XLOOKUP($A12, Rikillagaskada!$A7:$A65, Rikillagaskada!E7:E65, "No Match")} -> 0 | H12: {=XLOOKUP($A12, Rikillagaskada!$A7:$A65, Rikillagaskada!F7:F65, "No Match")} -> 2 | I12: 0 | J12: 0 | K12: 0 | L12: 0
A13: =$A$3 -> 46093 | B13: CE | C13: RAGALA | D13: {=XLOOKUP($A13, Ragala!$A7:$A66, Ragala!B7:B66, "No Match")} -> 0 | E13: {=XLOOKUP($A13, Ragala!$A7:$A66, Ragala!C7:C66, "No Match")} -> 2 | F13: {=XLOOKUP($A13, Ragala!$A7:$A66, Ragala!D7:D66, "No Match")} -> 0 | G13: {=XLOOKUP($A13, Ragala!$A7:$A66, Ragala!E7:E66, "No Match")} -> 0 | H13: {=XLOOKUP($A13, Ragala!$A7:$A66, Ragala!F7:F66, "No Match")} -> 2 | I13: {=XLOOKUP($A13, Ragala!$A7:$A66, Ragala!G7:G66, "No Match")} -> 0 | J13: {=XLOOKUP($A13, Ragala!$A7:$A66, Ragala!H7:H66, "No Match")} -> 0 | K13: {=XLOOKUP($A13, Ragala!$A7:$A66, Ragala!I7:I66, "No Match")} -> 0 | L13: {=XLOOKUP($A13, Ragala!$A7:$A66, Ragala!J7:J66, "No Match")} -> 0
A14: =$A$3 -> 46093 | B14: CE | C14: WALAPANE | D14: {=XLOOKUP($A14, Walapane!$A7:$A66, Walapane!B7:B66, "No Match")} -> 0 | E14: {=XLOOKUP($A14, Walapane!$A7:$A66, Walapane!C7:C66, "No Match")} -> 0 | F14: {=XLOOKUP($A14, Walapane!$A7:$A66, Walapane!D7:D66, "No Match")} -> 1 | G14: {=XLOOKUP($A14, Walapane!$A7:$A66, Walapane!E7:E66, "No Match")} -> 0 | H14: {=XLOOKUP($A14, Walapane!$A7:$A66, Walapane!F7:F66, "No Match")} -> 0 | I14: {=XLOOKUP($A14, Walapane!$A7:$A66, Walapane!G7:G66, "No Match")} -> 1 | J14: {=XLOOKUP($A14, Walapane!$A7:$A66, Walapane!H7:H66, "No Match")} -> 0 | K14: {=XLOOKUP($A14, Walapane!$A7:$A66, Walapane!I7:I66, "No Match")} -> 0 | L14: {=XLOOKUP($A14, Walapane!$A7:$A66, Walapane!J7:J66, "No Match")} -> 0
C15: Total | D15: =SUM(D3:D14) -> 8 | E15: =SUM(E3:E14) -> 14 | F15: =SUM(F3:F14) -> 13 | G15: =SUM(G3:G14) -> 2 | H15: =SUM(H3:H14) -> 9 | I15: =SUM(I3:I14) -> 9 | J15: =SUM(J3:J14) -> 4 | K15: =SUM(K3:K14) -> 2 | L15: =SUM(L3:L14) -> 1

Sheet Ampitiya
A1: Date | B1: Reported -Major Leaks | C1: Reported -Minor Leaks | D1: Reported -Service Leaks | E1: Repaired -Major Leaks | F1: Repaired -Minor Leaks | G1: Repaired -Service Leaks | H1: Balance -Major Leaks | I1: Balance -Minor Leaks | J1: Balance -Service Leaks
A2: 46049
A3: 46050
A4: 46051
A5: 46052
A6: 46053
A7: 46054 | B7: 3 | C7: 5 | D7: 4 | E7: 2 | F7: 4 | G7: 3 | H7: 1 | I7: 1 | J7: 1
A8: 46055 | B8: 4 | C8: 5 | D8: 6 | E8: 2 | F8: 4 | G8: 6 | H8: 2 | I8: 1 | J8: 0
A9: 46056 | B9: 5 | C9: 6 | D9: 6 | E9: 2 | F9: 3 | G9: 4 | H9: 3 | I9: 3 | J9: 2
A10: 46057 | B10: 5 | C10: 6 | D10: 5 | E10: 2 | F10: 3 | G10: 5 | H10: 3 | I10: 3 | J10: 0
A11: 46058 | B11: 7 | C11: 9 | D11: 6 | E11: 3 | F11: 8 | G11: 3 | H11: 4 | I11: 1 | J11: 3
A12: 46059 | B12: 6 | C12: 9 | D12: 8 | E12: 2 | F12: 7 | G12: 5 | H12: 4 | I12: 2 | J12: 3
A13: 46060 | B13: 6 | C13: 10 | D13: 11 | E13: 2 | F13: 6 | G13: 7 | H13: 4 | I13: 4 | J13: 4
A14: 46061 | B14: 8 | C14: 9 | D14: 7 | E14: 3 | F14: 6 | G14: 6 | H14: 5 | I14: 3 | J14: 1
A15: 46062 | B15: 8 | C15: 6 | D15: 6 | E15: 3 | F15: 4 | G15: 5 | H15: 5 | I15: 2 | J15: 1
A16: 46063 | B16: 7 | C16: 6 | D16: 5 | E16: 2 | F16: 4 | G16: 5 | H16: 5 | I16: 2 | J16: 0
A17: 46064 | B17: 7 | C17: 5 | D17: 4 | E17: 3 | F17: 4 | G17: 3 | H17: 4 | I17: 1 | J17: 1
A18: 46065 | B18: 6 | C18: 6 | D18: 5 | E18: 2 | F18: 3 | G18: 4 | H18: 4 | I18: 3 | J18: 1
... A93: 46140 | B93: 3 | C93: 3 | D93: 2 | E93: 2 | F93: 3 | G93: 2 | H93: 1 | I93: 0 | J93: 0
A94: 46141
A95: 46142

Sheet Digana 1
A1: Date | B1: Reported -Major Leaks | C1: Reported -Minor Leaks | D1: Reported -Service Leaks | E1: Repaired -Major Leaks | F1: Repaired -Minor Leaks | G1: Repaired -Service Leaks | H1: Balance -Major Leaks | I1: Balance -Minor Leaks | J1: Balance -Service Leaks
A2: 46049 | B2: 1 | C2: 1 | D2: 1 | E2: 1 | F2: 1 | G2: 1 | H2: 0 | I2: 0 | J2: 0
A3: 46050 | B3: 0 | C3: 0 | D3: 3 | E3: 0 | F3: 0 | G3: 3 | H3: 0 | I3: 0 | J3: 0
A4: 46051 | B4: 1 | C4: 1 | D4: 2 | E4: 1 | F4: 1 | G4: 2 | H4: 0 | I4: 0 | J4: 0
A5: 46052 | B5: 0 | C5: 0 | D5: 0 | E5: 0 | F5: 0 | G5: 0 | H5: 0 | I5: 0 | J5: 0
A6: 46053 | B6: 0 | C6: 0 | D6: 2 | E6: 0 | F6: 0 | G6: 1 | H6: 0 | I6: 0 | J6: 1
A7: 46054 | B7: 0 | C7: 0 | D7: 1 | E7: 0 | F7: 0 | G7: 2 | H7: 0 | I7: 0 | J7: 0
A8: 46055 | B8: 0 | C8: 0 | D8: 0 | E8: 0 | F8: 0 | G8: 0 | H8: 0 | I8: 0 | J8: 0
A9: 46056 | B9: 0 | C9: 0 | D9: 1 | E9: 0 | F9: 0 | G9: 1 | H9: 0 | I9: 0 | J9: 0
A10: 46057 | B10: 0 | C10: 1 | D10: 2 | E10: 0 | F10: 1 | G10: 2 | H10: 0 | I10: 0 | J10: 0
A11: 46058 | B11: 0 | C11: 1 | D11: 3 | E11: 0 | F11: 1 | G11: 3 | H11: 0 | I11: 0 | J11: 0
A12: 46059 | B12: 1 | C12: 0 | D12: 5 | E12: 1 | F12: 0 | G12: 5 | H12: 0 | I12: 0 | J12: 0
A13: 46060 | B13: 0 | C13: 0 | D13: 5 | E13: 0 | F13: 0 | G13: 5 | H13: 0 | I13: 0 | J13: 0
... A84: 46131 | B84: 0 | C84: 0 | D84: 0 | E84: 0 | F84: 0 | G84: 0 | H84: 0 | I84: 0 | J84: 3
A85: 46132
A86: 46133
A87: 46134
A88: 46135
A89: 46136
A90: 46137
A91: 46138
A92: 46139
A93: 46140
A94: 46141
A95: 46142

Sheet Digana 2
A1: Date | B1: Reported -Major Leaks | C1: Reported -Minor Leaks | D1: Reported -Service Leaks | E1: Repaired -Major Leaks | F1: Repaired -Minor Leaks | G1: Repaired -Service Leaks | H1: Balance -Major Leaks | I1: Balance -Minor Leaks | J1: Balance -Service Leaks
A2: 46049 | B2: 1 | C2: 1 | D2: 0 | E2: 2 | F2: 1 | G2: 0 | H2: 0 | I2: 0 | J2: 0
A3: 46050 | B3: 0 | C3: 0 | D3: 5 | E3: 0 | F3: 0 | G3: 4 | H3: 0 | I3: 0 | J3: 1
A4: 46051 | B4: 0 | C4: 3 | D4: 1 | E4: 0 | F4: 1 | G4: 1 | H4: 0 | I4: 2 | J4: 0
A5: 46052 | B5: 1 | C5: 0 | D5: 4 | E5: 0 | F5: 0 | G5: 4 | H5: 1 | I5: 0 | J5: 0
A6: 46053 | B6: 0 | C6: 2 | D6: 1 | E6: 1 | F6: 4 | G6: 1 | H6: 0 | I6: 0 | J6: 0
A7: 46054 | B7: 0 | C7: 0 | D7: 1 | E7: 0 | F7: 0 | G7: 0 | H7: 0 | I7: 0 | J7: 0
A8: 46055 | B8: 0 | C8: 1 | D8: 4 | E8: 0 | F8: 0 | G8: 4 | H8: 0 | I8: 1 | J8: 0
A9: 46056 | B9: 0 | C9: 0 | D9: 0 | E9: 0 | F9: 1 | G9: 0 | H9: 0 | I9: 0 | J9: 0
A10: 46057 | B10: 0 | C10: 0 | D10: 0 | E10: 0 | F10: 0 | G10: 0 | H10: 0 | I10: 0 | J10: 0
A11: 46058 | B11: 0 | C11: 1 | D11: 2 | E11: 0 | F11: 1 | G11: 1 | H11: 0 | I11: 0 | J11: 1
A12: 46059 | B12: 0 | C12: 2 | D12: 2 | E12: 0 | F12: 2 | G12: 3 | H12: 0 | I12: 0 | J12: 0
A13: 46060 | B13: 0 | C13: 1 | D13: 3 | E13: 0 | F13: 1 | G13: 2 | H13: 0 | I13: 0 | J13: 1
... A86: 46133 | B86: 0 | C86: 1 | D86: 2 | E86: 0 | F86: 1 | G86: 3 | H86: 0 | I86: 1 | J86: 0
A87: 46134
A88: 46135
A89: 46136
A90: 46137
A91: 46138
A92: 46139
A93: 46140
A94: 46141
A95: 46142

Sheet Balagolla
A1: Date | B1: Reported -Major Leaks | C1: Reported -Minor Leaks | D1: Reported -Service Leaks | E1: Repaired -Major Leaks | F1: Repaired -Minor Leaks | G1: Repaired -Service Leaks | H1: Balance -Major Leaks | I1: Balance -Minor Leaks | J1: Balance -Service Leaks
A2: 46049 | B2: 0 | C2: 0 | D2: 2 | E2: 0 | F2: 0 | G2: 2 | H2: 0 | I2: 0 | J2: 0
A3: 46050 | B3: 0 | C3: 0 | D3: 2 | E3: 0 | F3: 0 | G3: 2 | H3: 0 | I3: 0 | J3: 0
A4: 46051 | B4: 0 | C4: 1 | D4: 3 | E4: 0 | F4: 1 | G4: 3 | H4: 0 | I4: 0 | J4: 0
A5: 46052 | B5: 0 | C5: 1 | D5: 2 | E5: 0 | F5: 1 | G5: 2 | H5: 0 | I5: 0 | J5: 0
A6: 46053 | B6: 0 | C6: 0 | D6: 3 | E6: 0 | F6: 0 | G6: 3 | H6: 0 | I6: 0 | J6: 0
A7: 46054 | B7: 0 | C7: 1 | D7: 3 | E7: 0 | F7: 1 | G7: 3 | H7: 0 | I7: 0 | J7: 0
A8: 46055 | B8: 1 | C8: 0 | D8: 2 | E8: 1 | F8: 0 | G8: 2 | H8: 0 | I8: 0 | J8: 0
A9: 46056 | B9: 0 | C9: 0 | D9: 3 | E9: 0 | F9: 0 | G9: 3 | H9: 0 | I9: 0 | J9: 0
A10: 46057 | B10: 0 | C10: 0 | D10: 2 | E10: 0 | F10: 0 | G10: 2 | H10: 0 | I10: 0 | J10: 0
A11: 46058 | B11: 0 | C11: 0 | D11: 3 | E11: 0 | F11: 0 | G11: 3 | H11: 0 | I11: 0 | J11: 0
A12: 46059 | B12: 0 | C12: 0 | D12: 2 | E12: 0 | F12: 0 | G12: 2 | H12: 0 | I12: 0 | J12: 0
A13: 46060 | B13: 0 | C13: 0 | D13: 1 | E13: 0 | F13: 0 | G13: 1 | H13: 0 | I13: 0 | J13: 0
... A65: 46112 | B65: 0 | C65: 0 | D65: 2 | E65: 0 | F65: 0 | G65: 2 | H65: 0 | I65: 0 | J65: 0
A66: 46113
A67: 46114
A68: 46115
A69: 46116
A70: 46117
A71: 46118
A72: 46119
A73: 46120
A74: 46121
A75: 46122
A76: 46123
A77: 46124
... A95: 46142

Sheet Manikhinna
A1: Date | B1: Reported -Major Leaks | C1: Reported -Minor Leaks | D1: Reported -Service Leaks | E1: Repaired -Major Leaks | F1: Repaired -Minor Leaks | G1: Repaired -Service Leaks | H1: Balance -Major Leaks | I1: Balance -Minor Leaks | J1: Balance -Service Leaks
A2: 46049 | B2: 0 | C2: 0 | D2: 3 | E2: 0 | F2: 0 | G2: 3 | H2: 0 | I2: 0 | J2: 0
A3: 46050 | B3: 0 | C3: 1 | D3: 1 | E3: 0 | F3: 1 | G3: 1 | H3: 0 | I3: 0 | J3: 0
A4: 46051 | B4: 0 | C4: 1 | D4: 2 | E4: 0 | F4: 1 | G4: 2 | H4: 0 | I4: 0 | J4: 0
A5: 46052 | B5: 0 | C5: 0 | D5: 4 | E5: 0 | F5: 0 | G5: 4 | H5: 0 | I5: 0 | J5: 0
A6: 46053 | B6: 0 | C6: 0 | D6: 4 | E6: 0 | F6: 0 | G6: 4 | H6: 0 | I6: 0 | J6: 0
A7: 46054 | B7: 0 | C7: 0 | D7: 0 | E7: 0 | F7: 0 | G7: 0 | H7: 0 | I7: 0 | J7: 0
A8: 46055 | B8: 0 | C8: 0 | D8: 3 | E8: 0 | F8: 0 | G8: 3 | H8: 0 | I8: 0 | J8: 0
A9: 46056 | B9: 0 | C9: 1 | D9: 4 | E9: 0 | F9: 1 | G9: 4 | H9: 0 | I9: 0 | J9: 0
A10: 46057 | B10: 0 | C10: 1 | D10: 0 | E10: 0 | F10: 1 | G10: 0 | H10: 0 | I10: 0 | J10: 0
A11: 46058 | B11: 0 | C11: 1 | D11: 3 | E11: 0 | F11: 1 | G11: 3 | H11: 0 | I11: 0 | J11: 0
A12: 46059 | B12: 1 | C12: 2 | D12: 0 | E12: 1 | F12: 2 | G12: 0 | H12: 0 | I12: 0 | J12: 0
A13: 46060 | B13: 0 | C13: 4 | D13: 2 | E13: 0 | F13: 4 | G13: 2 | H13: 0 | I13: 0 | J13: 0
... A32: 46079 | B32: 0 | C32: 2 | D32: 4 | E32: 0 | F32: 2 | G32: 6 | H32: 0 | I32: 0 | J32: 0
A33: 46080 | B33: 0 | C33: 2 | D33: 1 | E33: 0 | F33: 2 | H33: 0 | I33: 0 | J33: 1
A34: 46081 | B34: 0 | C34: 0 | D34: 1 | E34: 0 | F34: 0 | G34: 2 | H34: 0 | I34: 0 | J34: 0
A35: 46082 | B35: 0 | C35: 1 | D35: 2 | E35: 0 | F35: 1 | G35: 2 | H35: 0 | I35: 0 | J35: 0
A36: 46083 | B36: 0 | C36: 2 | D36: 3 | E36: 0 | F36: 2 | G36: 3 | H36: 0 | I36: 0 | J36: 0
A37: 46084 | B37: 0 | C37: 1 | D37: 5 | E37: 0 | F37: 1 | G37: 5 | H37: 0 | I37: 0 | J37: 3
A38: 46085 | B38: 0 | C38: 2 | D38: 6 | E38: 0 | F38: 2 | G38: 6 | H38: 0 | I38: 0 | J38: 0
A39: 46086 | B39: 0 | C39: 1 | D39: 6 | E39: 0 | F39: 1 | G39: 5 | H39: 0 | I39: 0 | J39: 1
A40: 46087 | B40: 0 | C40: 1 | D40: 4 | E40: 0 | F40: 1 | G40: 3 | H40: 0 | I40: 0 | J40: 1
A41: 46088 | B41: 0 | C41: 0 | D41: 1 | E41: 0 | F41: 0 | G41: 0 | H41: 0 | I41: 0 | J41: 3
A42: 46089 | B42: 0 | C42: 0 | D42: 2 | E42: 0 | F42: 0 | G42: 2 | H42: 0 | I42: 0 | J42: 2
A43: 46090 | B43: 0 | C43: 0 | D43: 1 | E43: 0 | F43: 0 | G43: 3 | H43: 0 | I43: 0 | J43: 1
A44: 46091 | B44: 0 | C44: 0 | D44: 0 | E44: 0 | F44: 0 | G44: 0 | H44: 0 | I44: 0 | J44: 0
A45: 46092 | B45: 0 | C45: 0 | D45: 3 | E45: 0 | F45: 0 | G45: 1 | H45: 0 | I45: 0 | J45: 2
... A92: 46139 | B92: 0 | C92: 0 | D92: 3 | E92: 0 | F92: 0 | G92: 3 | H92: 0 | I92: 0 | J92: 0
A93: 46140
A94: 46141
A95: 46142

Sheet Buluwamuduna
A1: Date | B1: Reported -Major Leaks | C1: Reported -Minor Leaks | D1: Reported -Service Leaks | E1: Repaired -Major Leaks | F1: Repaired -Minor Leaks | G1: Repaired -Service Leaks | H1: Balance -Major Leaks | I1: Balance -Minor Leaks | J1: Balance -Service Leaks
A2: 46049 | B2: 1 | C2: 2 | D2: 3 | E2: 1 | F2: 2 | G2: 3 | H2: 0 | I2: 0 | J2: 0
A3: 46050 | B3: 0 | C3: 1 | D3: 2 | E3: 0 | F3: 1 | G3: 2 | H3: 0 | I3: 0 | J3: 0
A4: 46051 | B4: 0 | C4: 1 | D4: 4 | E4: 0 | F4: 1 | G4: 4 | H4: 0 | I4: 0 | J4: 0
A5: 46052 | B5: 0 | C5: 3 | D5: 2 | E5: 0 | F5: 3 | G5: 2 | H5: 0 | I5: 0 | J5: 0
A6: 46053 | B6: 0 | C6: 2 | D6: 1 | E6: 0 | F6: 2 | G6: 1 | H6: 0 | I6: 0 | J6: 0
A7: 46054 | B7: 0 | C7: 0 | D7: 0 | E7: 0 | F7: 0 | G7: 0 | H7: 0 | I7: 0 | J7: 0
A8: 46055 | B8: 1 | C8: 1 | D8: 1 | E8: 1 | F8: 1 | G8: 1 | H8: 0 | I8: 0 | J8: 0
A9: 46056 | B9: 0 | C9: 1 | D9: 2 | E9: 0 | F9: 1 | G9: 2 | H9: 0 | I9: 0 | J9: 0
A10: 46057 | B10: 0 | C10: 0 | D10: 1 | E10: 0 | F10: 0 | G10: 1 | H10: 0 | I10: 0 | J10: 0
A11: 46058 | B11: 0 | C11: 1 | D11: 2 | E11: 0 | F11: 1 | G11: 2 | H11: 0 | I11: 0 | J11: 0
A12: 46059 | B12: 0 | C12: 1 | D12: 2 | E12: 0 | F12: 1 | G12: 2 | H12: 0 | I12: 0 | J12: 0
A13: 46060 | B13: 0 | C13: 2 | D13: 3 | E13: 0 | F13: 2 | G13: 3 | H13: 0 | I13: 0 | J13: 0
... A91: 46138 | B91: 0 | C91: 0 | D91: 3 | E91: 0 | F91: 0 | G91: 3 | H91: 0 | I91: 0 | J91: 0
A92: 46139
A93: 46140
A94: 46141
A95: 46142

Sheet Medadumbara
A1: Date | B1: Reported -Major Leaks | C1: Reported -Minor Leaks | D1: Reported -Service Leaks | E1: Repaired -Major Leaks | F1: Repaired -Minor Leaks | G1: Repaired -Service Leaks | H1: Balance -Major Leaks | I1: Balance -Minor Leaks | J1: Balance -Service Leaks
A2: 46049 | B2: 0 | C2: 0 | D2: 3 | E2: 0 | F2: 0 | G2: 3 | H2: 0 | I2: 0 | J2: 0
A3: 46050 | B3: 0 | C3: 1 | D3: 10 | E3: 0 | F3: 1 | G3: 7 | H3: 0 | I3: 0 | J3: 3
A4: 46051 | B4: 0 | C4: 2 | D4: 12 | E4: 0 | F4: 2 | G4: 10 | H4: 0 | I4: 0 | J4: 2
A5: 46052 | B5: 0 | C5: 2 | D5: 8 | E5: 0 | F5: 2 | G5: 8 | H5: 0 | I5: 0 | J5: 0
A6: 46053 | B6: 0 | C6: 0 | D6: 4 | E6: 0 | F6: 0 | G6: 4 | H6: 0 | I6: 0 | J6: 0
A7: Total | B7: =SUM(B2:B6) -> 0 | C7: =SUM(C2:C6) -> 5 | D7: =SUM(D2:D6) -> 37 | E7: =SUM(E2:E6) -> 0 | F7: =SUM(F2:F6) -> 5 | G7: =SUM(G2:G6) -> 32 | H7: =SUM(H2:H6) -> 0 | I7: =SUM(I2:I6) -> 0 | J7: =SUM(J2:J6) -> 5
A9: 46054 | B9: 0 | C9: 2 | D9: 0 | E9: 0 | F9: 1 | G9: 0 | H9: 0 | I9: 0 | J9: 0
A10: 46055 | B10: 0 | C10: 1 | D10: 8 | E10: 0 | F10: 1 | G10: 8 | H10: 0 | I10: 0 | J10: 0
A11: 46056 | B11: 0 | C11: 0 | D11: 5 | E11: 0 | F11: 0 | G11: 5 | H11: 0 | I11: 0 | J11: 0
A12: 46057 | B12: 0 | C12: 0 | D12: 2 | E12: 0 | F12: 0 | G12: 2 | H12: 0 | I12: 0 | J12: 0
A13: 46058 | B13: 0 | C13: 0 | D13: 7 | E13: 0 | F13: 0 | G13: 7 | H13: 0 | I13: 0 | J13: 0
A14: 46059 | B14: 0 | C14: 0 | D14: 5 | E14: 0 | F14: 0 | G14: 5 | H14: 0 | I14: 0 | J14: 0
A15: 46060 | B15: 0 | C15: 0 | D15: 5 | E15: 0 | F15: 0 | G15: 5 | H15: 0 | I15: 0 | J15: 0
A16: 46061 | B16: 0 | C16: 0 | D16: 0 | E16: 0 | F16: 0 | G16: 0 | H16: 0 | I16: 0 | J16: 0
A17: 46062 | B17: 0 | C17: 1 | D17: 5 | E17: 0 | F17: 1 | G17: 4 | H17: 0 | I17: 0 | J17: 0
A18: 46063 | B18: 0 | C18: 2 | D18: 6 | E18: 0 | F18: 2 | G18: 5 | H18: 2 | I18: 1 | J18: 1
A19: 46064 | B19: 0 | C19: 1 | D19: 5 | E19: 0 | F19: 1 | G19: 4 | H19: 0 | I19: 0 | J19: 3
A20: 46065 | B20: 0 | C20: 1 | D20: 5 | E20: 0 | F20: 0 | G20: 4 | H20: 0 | I20: 0 | J20: 0
... A36: 46081 | B36: 0 | C36: 0 | D36: 6 | E36: 0 | F36: 0 | G36: 6 | H36: 0 | I36: 0 | J36: 0
A37: total | B37: =SUM(B2:B36) -> 0 | C37: =SUM(C9:C36) -> 25 | D37: =SUM(D9:D36) -> 154 | E37: =SUM(E9:E36) -> 0 | F37: =SUM(F9:F36) -> 18 | G37: =SUM(G9:G36) -> 132 | H37: =SUM(H9:H36) -> 2 | I37: =SUM(I9:I36) -> 4 | J37: =SUM(J9:J36) -> 17
A39: 46082 | B39: 0 | C39: 1 | D39: 3 | E39: 0 | F39: 1 | G39: 3 | H39: 0 | I39: 0 | J39: 0
A40: 46083 | B40: 0 | C40: 0 | D40: 4 | E40: 0 | F40: 0 | G40: 2 | H40: 0 | I40: 0 | J40: 0
A41: 46084 | B41: 0 | C41: 0 | D41: 0 | E41: 0 | F41: 0 | G41: 0 | H41: 0 | I41: 0 | J41: 0
A42: 46085 | B42: 0 | C42: 0 | D42: 2 | E42: 0 | F42: 0 | G42: 2 | H42: 0 | I42: 0 | J42: 0
A43: 46086 | B43: 0 | C43: 1 | D43: 7 | E43: 0 | F43: 1 | G43: 4 | H43: 0 | I43: 0 | J43: 0
A44: 46087 | B44: 0 | C44: 0 | D44: 2 | E44: 0 | F44: 0 | G44: 2 | H44: 0 | I44: 0 | J44: 0
A45: 46088 | B45: 0 | C45: 0 | D45: 6 | E45: 0 | F45: 0 | G45: 2 | H45: 0 | I45: 0 | J45: 4
A46: 46089 | B46: 0 | C46: 1 | D46: 6 | E46: 0 | F46: 0 | G46: 6 | H46: 0 | I46: 0 | J46: 0
A47: 46090 | B47: 0 | C47: 0 | D47: 2 | E47: 0 | F47: 0 | G47: 2 | H47: 0 | I47: 0 | J47: 0
A48: 46091 | B48: 0 | C48: 0 | D48: 10 | E48: 0 | F48: 0 | G48: 6 | H48: 0 | I48: 0 | J48: 4
A49: 46092 | B49: 0 | C49: 0 | D49: 4 | E49: 0 | F49: 0 | G49: 3 | H49: 0 | I49: 0 | J49: 1
A50: 46093 | B50: 0 | C50: 2 | D50: 3 | E50: 0 | F50: 0 | G50: 0 | H50: 0 | I50: 0 | J50: 0
... A62: 46105 | B62: 0 | C62: 1 | D62: 5 | E62: 0 | F62: 1 | G62: 5 | H62: 0 | I62: 0 | J62: 0
A63: 46106 | B63: 0 | C63: 2 | D63: 2 | E63: 0 | F63: 2 | G63: 2 | H63: 0 | J63: 0
A64: 46107 | B64: 0 | C64: 0 | D64: 3 | E64: 0 | F64: 0 | G64: 3 | H64: 0 | I64: 0 | J64: 0
A65: 46108 | B65: 0 | C65: 0 | D65: 2 | E65: 0 | F65: 0 | G65: 2 | H65: 0 | I65: 0 | J65: 0
A66: 46109 | B66: 0 | C66: 0 | D66: 8 | E66: 0 | F66: 0 | G66: 7 | H66: 0 | I66: 0 | J66: 2
A67: 46110 | B67: 0 | C67: 0 | D67: 2 | E67: 0 | F67: 0 | G67: 0 | H67: 0 | I67: 0 | J67: 0
A68: 46111 | B68: 0 | C68: 1 | D68: 5 | E68: 0 | F68: 0 | G68: 0 | H68: 0 | I68: 0 | J68: 0
...

Sheet Marassana
A1: Date | B1: Reported -Major Leaks | C1: Reported -Minor Leaks | D1: Reported -Service Leaks | E1: Repaired -Major Leaks | F1: Repaired -Minor Leaks | G1: Repaired -Service Leaks | H1: Balance -Major Leaks | I1: Balance -Minor Leaks | J1: Balance -Service Leaks
A2: 46049 | B2: 2 | C2: 2 | D2: 0 | E2: 2 | F2: 2 | G2: 0 | H2: 0 | I2: 0 | J2: 0
A3: 46050 | B3: 1 | C3: 1 | D3: 1 | E3: 1 | F3: 1 | G3: 1 | H3: 0 | I3: 0 | J3: 0
A4: 46051 | B4: 1 | C4: 1 | D4: 1 | E4: 1 | F4: 1 | G4: 1 | H4: 0 | I4: 0 | J4: 0
A5: 46052 | B5: 0 | C5: 0 | D5: 0 | E5: 0 | F5: 0 | G5: 0 | H5: 0 | I5: 0 | J5: 0
A6: 46053 | B6: 0 | C6: 2 | D6: 1 | E6: 0 | F6: 2 | G6: 0 | H6: 0 | I6: 0 | J6: 1
A7: 46054 | B7: 0 | C7: 0 | D7: 0 | E7: 0 | F7: 1 | G7: 0 | H7: 0 | I7: 0 | J7: 0
A8: 46055 | B8: 0 | C8: 3 | D8: 3 | E8: 0 | F8: 3 | G8: 2 | H8: 0 | I8: 0 | J8: 1
A9: 46056 | B9: 0 | C9: 1 | D9: 0 | E9: 0 | F9: 3 | G9: 0 | H9: 0 | I9: 0 | J9: 0
A10: 46057 | B10: 0 | C10: 1 | D10: 4 | E10: 1 | F10: 1 | G10: 4 | H10: 0 | I10: 0 | J10: 0
A11: 46058 | B11: 0 | C11: 0 | D11: 3 | E11: 0 | F11: 1 | G11: 0 | H11: 0 | I11: 0 | J11: 3
A12: 46059 | B12: 0 | C12: 0 | D12: 0 | E12: 1 | F12: 0 | G12: 0 | H12: 0 | I12: 0 | J12: 0
A13: 46060 | B13: 2 | C13: 1 | D13: 4 | E13: 2 | F13: 1 | G13: 0 | H13: 0 | I13: 0 | J13: 4
... A82: 46129 | B82: 1 | C82: 0 | D82: 0 | E82: 1 | F82: 0 | G82: 0 | H82: 0 | I82: 0 | J82: 2
A83: 46130 | B83: 1 | C83: 0 | D83: 0 | E83: 1 | F83: 0 | G83: 0 | I83: 0 | J83: 1
A84: 46131 | B84: 2 | C84: 0 | D84: 1 | E84: 0 | F84: 0 | G84: 0 | H84: 0 | I84: 0 | J84: 1
A85: 46132 | B85: 0 | C85: 2 | D85: 5 | E85: 0 | F85: 1 | G85: 1 | H85: 0 | I85: 0 | J85: 4
A86: 46133 | B86: 3 | C86: 0 | D86: 0 | E86: 3 | F86: 0 | G86: 0 | H86: 0 | I86: 0 | J86: 0
A87: 46134 | B87: 0 | C87: 1 | D87: 0 | E87: 0 | F87: 1 | G87: 4 | H87: 0 | I87: 0 | J87: 0
A88: 46135
A89: 46136
A90: 46137
A91: 46138
A92: 46139
A93: 46140
A94: 46141
A95: 46142

Sheet Haragama
A1: Date | B1: Reported -Major Leaks | C1: Reported -Minor Leaks | D1: Reported -Service Leaks | E1: Repaired -Major Leaks | F1: Repaired -Minor Leaks | G1: Repaired -Service Leaks | H1: Balance -Major Leaks | I1: Balance -Minor Leaks | J1: Balance -Service Leaks
A2: 46049 | B2: 0 | C2: 0 | D2: 0 | E2: 0 | F2: 0 | G2: 0 | H2: 0 | I2: 0 | J2: 0
A3: 46050 | B3: 0 | C3: 2 | D3: 1 | E3: 0 | F3: 2 | G3: 1 | H3: 0 | I3: 0 | J3: 0
A4: 46051 | B4: 0 | C4: 1 | D4: 1 | E4: 0 | F4: 1 | G4: 1 | H4: 0 | I4: 0 | J4: 0
A5: 46052 | B5: 0 | C5: 0 | D5: 1 | E5: 0 | F5: 0 | G5: 1 | H5: 0 | I5: 0 | J5: 0
A6: 46053 | B6: 0 | C6: 0 | D6: 2 | E6: 0 | F6: 0 | G6: 2 | H6: 0 | I6: 0 | J6: 0
A7: 46054 | B7: 0 | C7: 1 | D7: 2 | E7: 0 | F7: 0 | G7: 2 | H7: 0 | I7: 0 | J7: 0
A8: 46055 | B8: 0 | C8: 0 | D8: 3 | E8: 0 | F8: 0 | G8: 3 | H8: 0 | I8: 0 | J8: 0
A9: 46056 | B9: 0 | C9: 3 | D9: 1 | E9: 0 | F9: 3 | G9: 1 | H9: 0 | I9: 0 | J9: 2
A10: 46057 | B10: 0 | C10: 2 | D10: 1 | E10: 0 | F10: 2 | G10: 1 | H10: 0 | I10: 0 | J10: 1
A11: 46058 | B11: 0 | C11: 1 | D11: 1 | E11: 0 | F11: 1 | G11: 1 | H11: 0 | I11: 0 | J11: 0
A12: 46059 | B12: 0 | C12: 3 | D12: 3 | E12: 0 | F12: 3 | G12: 3 | H12: 0 | I12: 0 | J12: 0
A13: 46060 | B13: 1 | C13: 3 | D13: 0 | E13: 1 | F13: 3 | G13: 0 | H13: 0 | I13: 0 | J13: 0
... A91: 46138 | B91: 0 | C91: 0 | D91: 3 | E91: 0 | F91: 0 | G91: 3 | H91: 0 | I91: 0 | J91: 3
A92: 46139
A93: 46140
A94: 46141
A95: 46142

Sheet Rikillagaskada
A1: Date | B1: Reported -Major Leaks | C1: Reported -Minor Leaks | D1: Reported -Service Leaks | E1: Repaired -Major Leaks | F1: Repaired -Minor Leaks | G1: Repaired -Service Leaks | H1: Balance -Major Leaks | I1: Balance -Minor Leaks | J1: Balance -Service Leaks
A2: 46049 | B2: 0 | C2: 1 | D2: 2 | E2: 0 | F2: 1 | G2: 2 | H2: 0 | I2: 0 | J2: 0
A3: 46050 | B3: 3 | C3: 2 | D3: 2 | E3: 3 | F3: 2 | G3: 2 | H3: 0 | I3: 0 | J3: 0
A4: 46051 | B4: 1 | C4: 3 | D4: 1 | E4: 1 | F4: 3 | G4: 1 | H4: 0 | I4: 0 | J4: 0
A5: 46052 | B5: 1 | C5: 2 | D5: 0 | E5: 1 | F5: 2 | G5: 0 | H5: 0 | I5: 0 | J5: 0
A6: 46053 | B6: 2 | C6: 5 | D6: 1 | E6: 2 | F6: 5 | G6: 1 | H6: 0 | I6: 0 | J6: 0
A7: 46054 | B7: 0 | C7: 1 | E7: 0 | F7: 1 | G7: 0 | H7: 0 | I7: 0 | J7: 0
A8: 46055 | B8: 0 | C8: 1 | D8: 1 | E8: 0 | F8: 1 | G8: 1 | H8: 0 | I8: 0 | J8: 0
A9: 46056 | B9: 1 | C9: 0 | D9: 1 | E9: 1 | F9: 0 | G9: 1 | H9: 0 | I9: 0 | J9: 0
A10: 46057 | B10: 1 | C10: 6 | D10: 1 | E10: 1 | F10: 6 | G10: 1 | H10: 0 | I10: 0 | J10: 0
A11: 46058 | B11: 0 | C11: 2 | D11: 0 | E11: 0 | F11: 2 | G11: 0 | H11: 0 | I11: 0 | J11: 0
A12: 46059 | B12: 1 | C12: 2 | D12: 0 | E12: 1 | F12: 2 | H12: 0 | I12: 0 | J12: 0
A13: 46060 | B13: 2 | C13: 1 | D13: 1 | E13: 2 | F13: 1 | G13: 1 | H13: 0 | I13: 0 | J13: 0
A14: 46061 | B14: 1 | C14: 0 | D14: 0 | E14: 1 | F14: 0 | G14: 0 | H14: 0 | I14: 0 | J14: 0
A15: 46062 | B15: 1 | C15: 0 | D15: 3 | E15: 1 | F15: 0 | G15: 3 | H15: 0 | I15: 0 | J15: 0
A16: 46063 | B16: 2 | C16: 0 | D16: 2 | E16: 2 | F16: 0 | G16: 2 | H16: 0 | I16: 0 | J16: 0
A17: 46064 | B17: 1 | C17: 0 | D17: 0 | E17: 1 | F17: 0 | G17: 0 | H17: 0 | I17: 0 | J17: 0
A18: 46065 | B18: 1 | C18: 4 | D18: 1 | E18: 1 | F18: 4 | G18: 1 | H18: 0 | I18: 0 | J18: 0
A19: 46066 | B19: 1 | C19: 3 | D19: 0 | E19: 1 | F19: 3 | H19: 0 | I19: 0 | J19: 0
A20: 46067 | B20: 0 | C20: 2 | D20: 1 | E20: 0 | F20: 2 | G20: 1 | H20: 0 | I20: 0 | J20: 0
A21: 46068 | B21: 1 | C21: 0 | D21: 1 | E21: 1 | F21: 0 | G21: 1 | H21: 0 | I21: 0 | J21: 0
A22: 46069 | B22: 2 | C22: 3 | D22: 1 | E22: 2 | F22: 3 | G22: 1 | H22: 0 | I22: 0 | J22: 0
A23: 46070 | B23: 2 | C23: 1 | D23: 0 | E23: 2 | F23: 1 | G23: 0 | H23: 0 | I23: 0 | J23: 0
A24: 46071 | B24: 0 | C24: 2 | D24: 2 | E24: 0 | F24: 2 | G24: 2 | H24: 0 | I24: 0 | J24: 0
A25: 46072 | B25: 0 | C25: 1 | D25: 0 | E25: 0 | F25: 1 | G25: 0 | H25: 0 | I25: 0 | J25: 0
A26: 46073 | B26: 0 | C26: 1 | D26: 1 | E26: 0 | F26: 1 | G26: 1 | H26: 0 | I26: 0 | J26: 0
A27: 46074 | B27: 0 | C27: 2 | D27: 2 | E27: 0 | F27: 2 | G27: 2 | H27: 0 | I27: 0 | J27: 0
A28: 46075 | B28: 0 | C28: 0 | D28: 0 | E28: 0 | F28: 0 | G28: 0 | H28: 0 | I28: 0 | J28: 0
A29: 46076 | B29: 0 | C29: 2 | D29: 1 | E29: 0 | F29: 2 | G29: 1 | H29: 0 | I29: 0 | J29: 0
A30: 46077 | B30: 0 | C30: 2 | D30: 2 | E30: 0 | F30: 2 | G30: 2 | H30: 0 | I30: 0 | J30: 0
A31: 46078 | B31: 0 | C31: 3 | D31: 0 | E31: 0 | F31: 3 | G31: 0 | H31: 0 | I31: 0 | J31: 0
... A93: 46140 | B93: 0 | C93: 1 | D93: 0 | E93: 0 | F93: 1 | G93: 0 | H93: 0 | I93: 0 | J93: 0
A94: 46141
A95: 46142
A96: 46143

Sheet Ragala
A1: Date | B1: Reported -Major Leaks | C1: Reported -Minor Leaks | D1: Reported -Service Leaks | E1: Repaired -Major Leaks | F1: Repaired -Minor Leaks | G1: Repaird service leaks | H1: Balance -Major Leaks | I1: Balance -Minor Leaks | J1: Balance -Service Leaks
A2: 46049 | B2: 1 | C2: 1 | D2: 1 | E2: 1 | F2: 1 | G2: 1 | H2: 0 | I2: 0 | J2: 0
A3: 46050 | B3: 0 | C3: 1 | D3: 1 | E3: 0 | F3: 1 | G3: 1 | H3: 0 | I3: 0 | J3: 0
A4: 46051 | B4: 1 | C4: 1 | D4: 2 | E4: 1 | F4: 1 | G4: 1 | H4: 0 | I4: 0 | J4: 0
A5: 46052 | B5: 1 | C5: 1 | D5: 1 | E5: 1 | F5: 1 | G5: 1 | H5: 0 | I5: 0 | J5: 0
A6: 46053 | B6: 0 | C6: 2 | D6: 1 | E6: 0 | F6: 2 | G6: 2 | H6: 0 | I6: 0 | J6: 0
A7: 46054 | B7: 0 | C7: 0 | D7: 0 | E7: 0 | F7: 0 | G7: 0 | H7: 0 | I7: 0 | J7: 0
A8: 46055 | B8: 0 | C8: 1 | D8: 1 | E8: 0 | F8: 1 | G8: 1 | H8: 0 | I8: 0 | J8: 0
A9: 46056 | B9: 1 | C9: 2 | D9: 0 | E9: 1 | F9: 2 | G9: 0 | H9: 0 | I9: 0 | J9: 0
A10: 46057 | B10: 1 | C10: 2 | D10: 1 | E10: 1 | F10: 2 | G10: 1 | H10: 0 | I10: 0 | J10: 0
A11: 46058 | B11: 2 | C11: 0 | D11: 2 | E11: 2 | F11: 0 | G11: 2 | H11: 0 | I11: 0 | J11: 0
A12: 46059 | B12: 0 | C12: 2 | D12: 2 | E12: 0 | F12: 2 | G12: 2 | H12: 0 | I12: 0 | J12: 0
A13: 46060 | B13: 0 | C13: 0 | D13: 0 | E13: 0 | F13: 0 | G13: 0 | H13: 0 | I13: 0 | J13: 0
... A34: 46081 | B34: 1 | C34: 2 | D34: 0 | E34: 2 | F34: 1 | G34: 0 | H34: 0 | I34: 0 | J34: 0
A35: Total
A36: 46082 | B36: 0 | C36: 0 | D36: 0 | E36: 0 | F36: 0 | G36: 0 | H36: 0 | I36: 0 | J36: 0
A37: 46083 | B37: 0 | C37: 2 | D37: 0 | E37: 0 | F37: 2 | G37: 0 | H37: 0 | I37: 0 | J37: 0
A38: 46084 | B38: 1 | C38: 1 | D38: 1 | E38: 1 | F38: 1 | G38: 1 | H38: 0 | I38: 0 | J38: 0
A39: 46085 | B39: 0 | C39: 1 | D39: 1 | E39: 0 | F39: 1 | G39: 1 | H39: 0 | I39: 0 | J39: 0
A40: 46086 | B40: 1 | C40: 1 | D40: 2 | E40: 1 | F40: 1 | G40: 2 | H40: 0 | I40: 0 | J40: 0
A41: 46087 | B41: 1 | C41: 1 | D41: 1 | E41: 1 | F41: 1 | G41: 1 | H41: 0 | I41: 0 | J41: 0
A42: 46088 | B42: 0 | C42: 1 | D42: 2 | E42: 0 | F42: 1 | G42: 2 | H42: 0 | I42: 0 | J42: 0
A43: 46089 | B43: 1 | C43: 0 | D43: 1 | E43: 1 | F43: 0 | G43: 1 | H43: 0 | I43: 0 | J43: 0
A44: 46090 | B44: 1 | C44: 0 | D44: 0 | E44: 1 | F44: 0 | G44: 0 | H44: 0 | I44: 0 | J44: 0
A45: 46091 | B45: 1 | C45: 1 | D45: 0 | E45: 1 | F45: 1 | G45: 0 | H45: 0 | I45: 0 | J45: 0
A46: 46092 | B46: 1 | C46: 1 | D46: 0 | E46: 1 | F46: 1 | G46: 0 | H46: 0 | I46: 0 | J46: 0
A47: 46093 | B47: 0 | C47: 2 | D47: 0 | E47: 0 | F47: 2 | G47: 0 | H47: 0 | I47: 0 | J47: 0
... A94: 46139 | B94: 1 | C94: 1 | D94: 0 | E94: 1 | F94: 1 | G94: 0 | H94: 0 | I94: 0 | J94: 0
A95: 46140
A96: 46141
A97: 46142

Sheet Walapane
A1: Date | B1: Reported -Major Leaks | C1: Reported -Minor Leaks | D1: Reported -Service Leaks | E1: Repaired -Major Leaks | F1: Repaired -Minor Leaks | G1: Repaired -Service Leaks | H1: Balance -Minor Leaks | I1: Balance -Minor Leaks | J1: Balance -Minor Leaks
A2: 46049 | B2: 1 | C2: 0 | D2: 1 | E2: 1 | F2: 1 | G2: 1 | H2: 0 | I2: 0 | J2: 0
A3: 46050 | B3: 1 | C3: 0 | D3: 1 | E3: 0 | F3: 1 | G3: 1 | H3: 0 | I3: 0 | J3: 0
A4: 46051 | B4: 1 | C4: 0 | D4: 1 | E4: 1 | F4: 1 | G4: 1 | H4: 0 | I4: 0 | J4: 0
A5: 46052 | B5: 1 | C5: 0 | D5: 1 | E5: 1 | F5: 0 | G5: 1 | H5: 0 | I5: 0 | J5: 0
A6: 46053 | B6: 0 | C6: 1 | D6: 1 | E6: 0 | F6: 1 | G6: 1 | H6: 0 | I6: 0 | J6: 0
A7: 46054 | B7: 0 | C7: 0 | D7: 0 | E7: 0 | F7: 0 | G7: 0 | H7: 0 | I7: 0 | J7: 0
A8: 46055 | B8: 1 | C8: 1 | D8: 0 | E8: 1 | F8: 1 | G8: 0 | H8: 0 | I8: 0 | J8: 0
A9: 46056 | B9: 2 | C9: 0 | D9: 2 | E9: 1 | F9: 0 | G9: 2 | H9: 0 | I9: 0 | J9: 0
A10: 46057 | B10: 1 | C10: 1 | D10: 2 | E10: 1 | F10: 2 | G10: 2 | H10: 0 | I10: 0 | J10: 0
A11: 46058 | B11: 1 | C11: 1 | D11: 1 | E11: 1 | F11: 1 | G11: 1 | H11: 0 | I11: 0 | J11: 0
A12: 46059 | B12: 2 | C12: 0 | D12: 2 | E12: 0 | F12: 2 | G12: 2 | H12: 0 | I12: 0 | J12: 0
A13: 46060 | B13: 1 | C13: 0 | D13: 1 | E13: 1 | F13: 0 | G13: 1 | H13: 0 | I13: 0 | J13: 0 | K13: 2
A14: 46061 | B14: 0 | C14: 0 | D14: 0 | E14: 0 | F14: 0 | G14: 0 | H14: 0 | I14: 0 | J14: 0
A15: 46062 | B15: 1 | C15: 1 | D15: 0 | E15: 1 | F15: 1 | G15: 0 | H15: 0 | I15: 0 | J15: 0
A16: 46063 | B16: 0 | C16: 2 | D16: 0 | E16: 0 | F16: 2 | G16: 0 | H16: 0 | I16: 0 | J16: 0
A17: 46064 | B17: 2 | C17: 0 | D17: 0 | E17: 0 | F17: 0 | G17: 0 | H17: 0 | I17: 0 | J17: 0
A18: 46065 | B18: 1 | C18: 1 | D18: 0 | E18: 1 | F18: 1 | G18: 0 | H18: 0 | I18: 0 | J18: 0
A19: 46066 | B19: 1 | C19: 1 | D19: 1 | E19: 1 | F19: 1 | G19: 1 | H19: 0 | I19: 0 | J19: 0
A20: 46067 | B20: 1 | C20: 0 | D20: 1 | E20: 1 | F20: 0 | G20: 1 | H20: 0 | I20: 0 | J20: 0
A21: 46068 | B21: 0 | C21: 0 | D21: 1 | E21: 0 | F21: 0 | G21: 1 | H21: 0 | I21: 0 | J21: 0
A22: 46069 | B22: 4 | C22: 1 | D22: 1 | E22: 4 | F22: 1 | G22: 1 | H22: 0 | I22: 0 | J22: 0
A23: 46070 | B23: 0 | C23: 1 | D23: 1 | E23: 0 | F23: 1 | G23: 1 | H23: 0 | I23: 0 | J23: 0
A24: 46071 | B24: 2 | C24: 0 | D24: 2 | E24: 2 | F24: 0 | G24: 2 | H24: 0 | I24: 0 | J24: 0
A25: 46072 | B25: 1 | C25: 1 | D25: 1 | E25: 1 | F25: 1 | G25: 1 | H25: 0 | I25: 0 | J25: 0
... A34: 46081 | B34: 2 | C34: 1 | D34: 3 | E34: 2 | F34: 1 | G34: 3 | H34: 0 | I34: 0 | J34: 0
A35: Total
A36: 46082 | B36: 0 | C36: 0 | D36: 0 | E36: 0 | F36: 0 | G36: 0 | H36: 0 | I36: 0 | J36: 0
A37: 46083 | B37: 0 | C37: 3 | D37: 0 | E37: 0 | F37: 3 | G37: 0 | H37: 0 | I37: 0 | J37: 0
A38: 46084 | B38: 0 | C38: 2 | D38: 1 | E38: 0 | F38: 2 | G38: 1 | H38: 0 | I38: 0 | J38: 0
A39: 46085 | B39: 2 | C39: 1 | D39: 3 | E39: 2 | F39: 1 | G39: 3 | H39: 0 | I39: 0 | J39: 0
A40: 46086 | B40: 0 | C40: 2 | D40: 2 | E40: 0 | F40: 2 | G40: 2 | H40: 0 | I40: 0 | J40: 0
A41: 46087 | B41: 2 | C41: 1 | D41: 1 | E41: 2 | F41: 1 | G41: 1 | H41: 0 | I41: 0 | J41: 0
A42: 46088 | B42: 1 | C42: 1 | D42: 1 | E42: 1 | F42: 1 | G42: 1 | H42: 0 | I42: 0 | J42: 0
A43: 46089 | B43: 0 | C43: 0 | D43: 0 | E43: 0 | F43: 0 | G43: 0 | H43: 0 | I43: 0 | J43: 0
A44: 46090 | B44: 2 | C44: 0 | D44: 1 | E44: 2 | F44: 0 | G44: 1 | H44: 0 | I44: 0 | J44: 0
A45: 46091 | B45: 0 | C45: 0 | D45: 0 | E45: 0 | F45: 0 | G45: 2 | H45: 0 | I45: 0 | J45: 0
A46: 46092 | B46: 1 | C46: 2 | D46: 0 | E46: 1 | F46: 2 | G46: 0 | H46: 0 | I46: 0 | J46: 0
A47: 46093 | B47: 0 | C47: 0 | D47: 1 | E47: 0 | F47: 0 | G47: 1 | H47: 0 | I47: 0 | J47: 0
... A95: 46140 | B95: 0 | C95: 1 | D95: 1 | E95: 0 | F95: 1 | G95: 1 | H95: 0 | I95: 0 | J95: 0
...
